# c++11

### lambda表达式：

~~~ c++
	auto function_name = [List of captures](List of parameters)->Return value{
   	 	return ;
	}
	int (*my_Add)(int, int) = [](int a, int b)->int {
		return a + b;
	};
~~~

### 类型转换：

1. static_cast：
   1. 对比dynamic_cast，缺乏运行时的安全检测
   2. 不能交叉转换（交叉转换：不同自定义数据类型的转换）
   3. 常用于基本数据类型，非const转换为const
2. dynamic_cast：有运行时的多态安全检测，如果不安全，指针将成为nullptr
3. reinterpret_cast：比较底层的强制类型转换，没有任何类型检查和格式转换，仅仅是简单的二进制数据拷贝
4. const_cast：去除常变量的const属性，只能调节类型限定符，不能更改基础类型

~~~ c++
xx_cast<type>(expression);
~~~

### 类内枚举：

~~~ c++
class Thing {
public:
	enum class egg {small,medium,big};
	enum class t_shirt { small, medium, big };
};
int main()
{
	Thing::egg nudan = Thing::egg::big;
	Thing::t_shirt my_tt = Thing::t_shirt::medium;
	return 0;
}
~~~

### 异常-抛出：

~~~ c++
try{
    //可能发生异常的语句
}catch(...){
    //处理异常
}
void function()//可能发生多种未知异常
{
    
}
void function()throw()//不会发生异常
{
    
}
void function()throw(arg)//声明可能发生的异常类型
{
    
}
~~~

1. 异常抛出后正确处理即可使部分剩余代码正常执行，若不处理异常则程序终止

2. 异常抛出后，try之后的代码块的语句不再执行，执行catch中的语句，后顺次正常执行之后语句

3. 一个异常可以有多个catch语句，处理可能发生的不同异常

4. throw（ ...）；主动抛出异常，如果有catch处理异常则按1中执行，若没有处理继续抛给调用该函数的函数，无法抛给下一个函数（throw抛出到main函数），进程终止

5. throw（...）, catch（typename identifier）{ }  将抛出的...赋予identifier，异常的类型被识别由对应的catch处理，有严格的类型匹配

6. 异常类型：

   1. （...）代表任何类型的异常

   2. 可以使用自定义异常类型来使异常更具体

   3. 系统定义的异常类型

      | 异常                  | 描述                                                         |
      | --------------------- | ------------------------------------------------------------ |
      | std::exception        | 该异常是所有标准c++异常的父类                                |
      | std::bad_alloc        | 该异常可以通过new抛出                                        |
      | std::bad_cast         | 该异常可以通过dynamic_cast抛出                               |
      | std::bad_exception    | 这在处理c++程序中无法预期的异常时非常有用                    |
      | std::bad_typeid       | 该异常可以通过typeid抛出                                     |
      | std::logic_error      | 理论上可以通过读取代码检测到的异常                           |
      | std::domain_error     | 当使用了一个无效的数学域时会抛出该异常                       |
      | std::invalid_argument | 当使用了一个无效的参数时会抛出该异常                         |
      | std::length_error     | 当创建了太长的std::string时会抛出该异常                      |
      | std::out_of_range     | 该异常可以通过方法抛出例如std::vevtor 和std::bitset<>::operator[]() |
      | std::runtime_error    | 理论上不可以通过检测代码读取到的异常                         |
      | std::overflow_error   | 当发生数学上溢时会抛出该异常                                 |
      | std::range_error      | 当尝试储存超处范围的值时会抛出该异常                         |
      | std::underflow_error  | 当发生数学下溢时会抛出该异                                   |


### 智能指针:

在当前代码块结束后堆空间的对象也可以自动销毁，无需手动管理内存

1. ~~~ c++
   auto_ptr<Person>p(new Person(10));//auto_ptr无法指向数组
   ~~~

2. ~~~ c++
   shared_ptr<Person[]>p(new Person[5]);
   ~~~

   1. shared_ptr可以指向数组，当前代码块时数组中的对象依次析构

   2. 可以有多个shared_ptr指向同一个对象，每多一个指向该对象的shared_ptr就会使强引用计数加1，当强引用计数为0时对象销毁

      注意：shared_ptr指向同一个对象时可以嵌套，但不可以独立在两个代码块里，不能使强引用计数多次为0

3. ~~~ c++
   shared_ptr<Person>p1(new Person(10));
   weak_ptr<Person>p2(p1);
   ~~~

   weak_ptr不能直接指向某个对象，需要通过shared_ptr初始化，使shared_ptr的强引用计数转换为弱引用计数：有多个指向该对象的shared_ptr不会增加计数，一旦某一个shared_ptr对象销毁，该对象析构

4. ~~~ c++
   unique_ptr<Person>p(new Person(10));
   ~~~

   1. unique_ptr对象始终是关联的原始指针的唯一所有者。我们无法复制unique_ptr对象，它只能移动。
   2. 由于每个unique_ptr对象都是原始指针的唯一所有者，因此在其析构函数中它直接删除关联的指针，不需要任何参考计数。

   
